Workbook

Sheet Itinerary
A1: Hari | B1: Tarikh | C1: Masa | D1: Aktiviti / Lokasi | E1: Solat | F1: Makan (Halal) | G1: Transport / Nota | H1: Kategori | I1: Kos/orang (¥) | J1: Kos/orang (₩)
A2: 1 (Rabu) | B2: 6 Jan 2027 | C2: 09:15 | D2: Landed KIX (Peach MM712, confirmed — pagi, BUKAN malam)
A3: 1 | B3: 6 Jan 2027 | C3: 09:15 | D3: Imigresen + bagasi | G3: ~30-45min
A4: 1 | B4: 6 Jan 2027 | C4: 10:15 | D4: Nankai Airport Express → Namba | G4: Nankai Airport Express, ¥970, ~45min | H4: Transport | I4: 970 | J4: =I4*'Budget Summary'!$B$2
A5: 1 | B5: 6 Jan 2027 | C5: 11:00 | D5: Sampai Namba — Kuromon Market (bags dulu, check-in guesthouse biasa 3pm) | G5: Simpan bagasi kat coin locker stesen kalau nak
A6: 1 | B6: 6 Jan 2027 | C6: 12:00 | D6: Zohor (kawasan Namba/Kuromon) | E6: Zohor 12:00
A7: 1 | B7: 6 Jan 2027 | C7: 12:30 | D7: Lunch — halal dekat Kuromon/Namba (guesthouse belum check-in) | F7: Makan luar (halal) | H7: Food-Luar | I7: 1500 | J7: =I7*'Budget Summary'!$B$2
A8: 1 | B8: 6 Jan 2027 | C8: 14:00 | D8: Check-in guesthouse, letak bagasi
A9: 1 | B9: 6 Jan 2027 | C9: 14:35 | D9: Asar | E9: Asar 14:35
A10: 1 | B10: 6 Jan 2027 | C10: 15:00 | D10: Explore Namba/Shinsaibashi (santai, tak payah rush hari pertama)
A11: 1 | B11: 6 Jan 2027 | C11: 17:00 | D11: Maghrib | E11: Maghrib 17:00
A12: 1 | B12: 6 Jan 2027 | C12: 17:30 | D12: Dinner — halal dekat Dotonbori/Namba | F12: Makan luar (halal) | H12: Food-Luar | I12: 1800 | J12: =I12*'Budget Summary'!$B$2
A13: 1 | B13: 6 Jan 2027 | C13: 18:20 | D13: Isyak | E13: Isyak 18:20
A14: 1 | B14: 6 Jan 2027 | C14: 19:00 | D14: Dotonbori night walk — Glico sign, canal, kushikatsu crawl (window-shop je kalau dah makan)
A15: 1 | B15: 6 Jan 2027 | C15: 21:30 | D15: Balik guesthouse, rehat
A16: 2 (Khamis) | B16: 7 Jan 2027 | C16: 05:38 | D16: Subuh | E16: Subuh 05:38
A17: 2 | B17: 7 Jan 2027 | C17: 06:30 | D17: Breakfast — masak simple kat guesthouse (roti/telur) | F17: Masak | G17: SAHKAN dapur guesthouse ada | H17: Food-Masak | I17: 500 | J17: =I17*'Budget Summary'!$B$2
A18: 2 | B18: 7 Jan 2027 | C18: 08:00 | D18: Beli Osaka Amazing Pass 1-day | G18: Cover metro + Castle + Umeda Sky + Tsutenkaku | H18: Pass | I18: 3500 | J18: =I18*'Budget Summary'!$B$2
A19: 2 | B19: 7 Jan 2027 | C19: 09:00 | D19: Osaka Castle
A20: 2 | B20: 7 Jan 2027 | C20: 12:00 | D20: Zohor (kawasan taman castle) | E20: Zohor 12:00
A21: 2 | B21: 7 Jan 2027 | C21: 12:30 | D21: Lunch — halal dekat Umeda/Namba | F21: Makan luar (halal) | H21: Food-Luar | I21: 1500 | J21: =I21*'Budget Summary'!$B$2
A22: 2 | B22: 7 Jan 2027 | C22: 14:00 | D22: Umeda Sky Building (PENTING: free entry tutup 3pm!) | G22: Guna Amazing Pass sebelum 15:00
A23: 2 | B23: 7 Jan 2027 | C23: 14:35 | D23: Asar | E23: Asar 14:35
A24: 2 | B24: 7 Jan 2027 | C24: 15:30 | D24: Tsutenkaku Tower / Shinsekai | G24: Guna Amazing Pass
A25: 2 | B25: 7 Jan 2027 | C25: 17:00 | D25: Maghrib | E25: Maghrib 17:00
A26: 2 | B26: 7 Jan 2027 | C26: 17:30 | D26: Dinner — halal Shinsekai (sebelum naik bas) | F26: Makan luar (halal) | H26: Food-Luar | I26: 1800 | J26: =I26*'Budget Summary'!$B$2
A27: 2 | B27: 7 Jan 2027 | C27: 18:20 | D27: Isyak | E27: Isyak 18:20
A28: 2 | B28: 7 Jan 2027 | C28: 19:00 | D28: Balik guesthouse, kemas beg
A29: 2 | B29: 7 Jan 2027 | C29: 23:00 | D29: Bas overnight Osaka → Tokyo (tidur atas bas) | G29: Willer Express, ¥2,000-4,000, ~8-9j | H29: Transport | I29: 3000 | J29: =I29*'Budget Summary'!$B$2
A30: 3 (Jumaat) | B30: 8 Jan 2027 | C30: ~05:22 | D30: Subuh (atas bas — anggar kiblat/qada bila sampai) | E30: Subuh ~05:22
A31: 3 | B31: 8 Jan 2027 | C31: ~07:30 | D31: Sampai Tokyo (bus terminal Shinjuku) | G31: Freshen up kat terminal
A32: 3 | B32: 8 Jan 2027 | C32: 08:00 | D32: Breakfast — onigiri/roti halal-safe | F32: Makan luar (halal) | H32: Food-Luar | I32: 600 | J32: =I32*'Budget Summary'!$B$2
A33: 3 | B33: 8 Jan 2027 | C33: 08:30 | D33: Local transport Tokyo (metro/IC card) | G33: ~¥800/hari | H33: Transport | I33: 800 | J33: =I33*'Budget Summary'!$B$2
A34: 3 | B34: 8 Jan 2027 | C34: 09:00 | D34: Asakusa Senso-ji (percuma)
A35: 3 | B35: 8 Jan 2027 | C35: 11:47 | D35: Zohor (cadangan: Tokyo Camii, Yoyogi-Uehara) | E35: Zohor 11:47
A36: 3 | B36: 8 Jan 2027 | C36: 12:15 | D36: Lunch — halal dekat Tokyo Camii/Shin-Okubo | F36: Makan luar (halal) | H36: Food-Luar | I36: 1800 | J36: =I36*'Budget Summary'!$B$2
A37: 3 | B37: 8 Jan 2027 | C37: 14:20 | D37: Asar | E37: Asar 14:20
A38: 3 | B38: 8 Jan 2027 | C38: 14:30 | D38: Shibuya / Harajuku
A39: 3 | B39: 8 Jan 2027 | C39: 16:45 | D39: Maghrib | E39: Maghrib 16:45
A40: 3 | B40: 8 Jan 2027 | C40: 17:15 | D40: Dinner — halal Shinjuku area | F40: Makan luar (halal) | H40: Food-Luar | I40: 2000 | J40: =I40*'Budget Summary'!$B$2
...

Sheet Budget Summary
A1: Andaian (Assumptions)
A2: Kadar tukaran ¥ → ₩ | B2: 9 | C2: ≈ kadar semasa; SEMAK semula sebelum trip (₩/¥ berubah)
A4: Kos Dah Bayar (Sunk cost)
A5: Item | B5: /orang (₩) | C5: Sumber
A6: Flight round-trip (Peach MM712) | B6: 304000 | C6: Tiket dah booking ✓
A7: Guesthouse Osaka (6 malam) | B7: 52000 | C7: Trip.com booking ✓
A8: Jumlah dah bayar | B8: =SUM(B6:B7)
A10: Kos Baru — ikut Kategori (auto dari sheet Itinerary)
A11: Kategori | B11: /orang (¥) | C11: /orang (₩) | D11: 6 orang (₩)
A12: Transport (bas/train intercity + local) | B12: =SUMIF(Itinerary!$H$2:$H$86,E12,Itinerary!$I$2:$I$86) | C12: =B12*$B$2 | D12: =C12*6 | E12: Transport
A13: Osaka Amazing Pass | B13: =SUMIF(Itinerary!$H$2:$H$86,E13,Itinerary!$I$2:$I$86) | C13: =B13*$B$2 | D13: =C13*6 | E13: Pass
A14: Penginapan tambahan (manga cafe Tokyo x2) | B14: =SUMIF(Itinerary!$H$2:$H$86,E14,Itinerary!$I$2:$I$86) | C14: =B14*$B$2 | D14: =C14*6 | E14: Accommodation
A15: Makanan — masak sendiri | B15: =SUMIF(Itinerary!$H$2:$H$86,E15,Itinerary!$I$2:$I$86) | C15: =B15*$B$2 | D15: =C15*6 | E15: Food-Masak
A16: Makanan — makan luar (halal) | B16: =SUMIF(Itinerary!$H$2:$H$86,E16,Itinerary!$I$2:$I$86) | C16: =B16*$B$2 | D16: =C16*6 | E16: Food-Luar
A17: Makanan — bekal dibawa | B17: =SUMIF(Itinerary!$H$2:$H$86,E17,Itinerary!$I$2:$I$86) | C17: =B17*$B$2 | D17: =C17*6 | E17: Food-Bekal
A18: Attraction optional (boleh skip) | B18: =SUMIF(Itinerary!$H$2:$H$86,E18,Itinerary!$I$2:$I$86) | C18: =B18*$B$2 | D18: =C18*6 | E18: Attraction-Optional
A19: Jumlah kos baru (termasuk optional) | B19: =SUM(B12:B18) | C19: =SUM(C12:C18) | D19: =SUM(D12:D18)
A21: Shopping & buffer (anggaran, bukan formula) | B21: 10000 | C21: =B21*$B$2 | D21: =C21*6
A23: GRAND TOTAL / orang (₩) | C23: =B8+C19+C21
A24: GRAND TOTAL / 6 orang (₩) | C24: =C23*6
A26: Nota: Food-Bekal (Hari 5 lunch) dah termasuk dalam pembelian Hari 4 dinner. Kos masak = anggaran groceries sahaja, ANDAI guesthouse ada dapur — SAHKAN dengan host dulu.

Sheet Waktu Solat Rujukan
A1: Anggaran Waktu Solat (6-12 Jan) — SAHKAN dengan app (Muslim Pro/IslamicFinder) bila sampai
A3: Waktu | B3: Osaka/Kansai | C3: Tokyo/Kawaguchiko
A4: Subuh | B4: ~05:38 | C4: ~05:22
A5: Syuruk (matahari terbit) | B5: ~07:05 | C5: ~06:51
A6: Zohor | B6: ~12:00 | C6: ~11:47
A7: Asar | B7: ~14:35 | C7: ~14:20
A8: Maghrib | B8: ~17:00 | C8: ~16:45
A9: Isyak | B9: ~18:20 | C9: ~18:05
A11: Sumber matahari terbit/terbenam: National Astronomical Observatory of Japan (NAOJ), Jan 2026 data (guna sebagai anggaran — beza tahun 2027 hanya saat, boleh abaikan).
A13: PENTING — Hari 3, 5, 6: Subuh mungkin jatuh time atas bas overnight. Sedia air sembahyang/tayammum kering, guna qiblat app, dan boleh jamak/qada bila sampai destinasi kalau betul-betul tak boleh solat atas bas.
